好的，作为一名顶级的Python教育专家，我将为你生成关于 `try-except-else-finally` 的详细教学内容。

---

## try-except-else-finally

### 🎯 核心概念
`try-except-else-finally` 是Python中一套强大的错误处理机制，它能让你的程序在遇到意外错误（即“异常”）时不会崩溃，而是按照你预设的方案优雅地处理问题，保证程序的健壮性。

### 💡 使用方式
这套结构就像一个完整的“应急预案”，它由四个代码块组成，每个都有明确的分工：

- **`try`**: 包含你**尝试**运行的代码块。这是主要的工作区域，但也可能是错误的来源。
- **`except`**: 如果 `try` 块中**发生错误**，Python会立即跳到 `except` 块。这里是处理意外的“急诊室”。你可以指定捕获特定类型的错误。
- **`else`**: 如果 `try` 块中**没有发生任何错误**，代码会顺利执行完 `try` 块，然后进入 `else` 块。这里是“庆功宴”，用于处理成功后的逻辑。
- **`finally`**: **无论是否发生错误**，`finally` 块中的代码**总会**在最后执行。这里是“清理战场”的地方，常用于释放资源，如关闭文件或网络连接。

**基本结构:**
```python
try:
    # 尝试执行的代码
    ...
except ExceptionType as e:
    # 如果发生指定类型的异常，执行这里的代码
    ...
else:
    # 如果没有发生异常，执行这里的代码
    ...
finally:
    # 无论如何都会执行的代码
    ...
```

### 📚 Level 1: 基础认知（30秒理解）
想象一下你在做一个除法计算器。最常见的错误就是用户试图除以零。如果没有错误处理，程序会立刻崩溃。`try-except` 就是你的第一道防线。

```python
# Level 1: 最简单的 try-except 结构

def simple_divider(numerator, denominator):
    print(f"--- 尝试计算 {numerator} / {denominator} ---")
    try:
        # 尝试执行可能会出错的代码
        result = numerator / denominator
        print(f"计算成功！结果是: {result}")
    except ZeroDivisionError:
        # 如果发生了 ZeroDivisionError（除零错误），就执行这里的代码
        print("💥 错误：分母不能为零！")

# 场景1: 正常计算
simple_divider(10, 2)

# 场景2: 触发错误
simple_divider(10, 0)

# --- 预期输出 ---
# --- 尝试计算 10 / 2 ---
# 计算成功！结果是: 5.0
# --- 尝试计算 10 / 0 ---
# 💥 错误：分母不能为零！
```
> **看到了吗？** 当我们试图用10除以0时，程序没有崩溃报错，而是打印了我们预设的友好提示。这就是异常处理的魅力！

### 📈 Level 2: 核心特性（深入理解）
现在，让我们把“应急预案”的另外两个成员 `else` 和 `finally` 请出来，看看完整的流程是什么样的。

#### 特性1: 捕获多种特定异常
一个 `try` 块后面可以跟多个 `except` 块，用于处理不同类型的错误。这就像医院里有不同的科室处理不同的病症。

```python
# Level 2, 特性1: 处理多种不同类型的错误

def process_data(data, index):
    print(f"\n--- 正在处理数据: {data} 在索引 {index} ---")
    try:
        # 可能会发生两种错误：索引越界 或 类型错误
        number = data[index]
        result = 100 / number
        print(f"处理成功，结果是 {result}")
    except IndexError:
        # 只捕获索引错误
        print("🚨 错误：索引超出范围了！")
    except (TypeError, ZeroDivisionError) as e:
        # 可以用元组捕获多种类型的错误，并用 as e 获取错误对象
        print(f"🚫 错误：发生计算错误！具体原因: {e}")
    except Exception as e:
        # Exception 是所有错误的父类，可以捕获任何未被捕获的异常
        print(f"🤔 捕获到未知错误: {e}")


# 场景1: 索引越界
process_data([1, 2, 3], 5)

# 场景2: 除以零
process_data([1, 0, 3], 1)

# 场景3: 类型错误
process_data([1, "hello", 3], 1)

# --- 预期输出 ---
# --- 正在处理数据: [1, 2, 3] 在索引 5 ---
# 🚨 错误：索引超出范围了！
#
# --- 正在处理数据: [1, 0, 3] 在索引 1 ---
# 🚫 错误：发生计算错误！具体原因: division by zero
#
# --- 正在处理数据: [1, 'hello', 3] 在索引 1 ---
# 🚫 错误：发生计算错误！具体原因: unsupported operand type(s) for /: 'int' and 'str'
```

#### 特性2: `else` 与 `finally` 的协作
`else` 和 `finally` 让我们的错误处理逻辑更完整、更清晰。`else` 负责“成功路径”，`finally` 负责“必定清理”。

```python
# Level 2, 特性2: 完整的 try-except-else-finally 流程

def access_resource(should_fail):
    print(f"\n--- 尝试访问资源 (失败模式: {should_fail}) ---")
    resource = None
    try:
        print("1. [try] 正在尝试打开资源...")
        if should_fail:
            # 模拟一个错误
            raise ValueError("资源访问失败！")
        resource = "宝贵的资源数据"
        print("2. [try] 资源访问成功！")
    except ValueError as e:
        print(f"3. [except] 捕获到错误: {e}")
    else:
        # 只有在 try 块没有异常时才会执行
        print(f"4. [else] 成功处理资源: {resource}")
    finally:
        # 无论如何都会执行
        print("5. [finally] 清理工作开始，关闭资源...")

# 场景1: 成功执行
access_resource(should_fail=False)

# 场景2: 发生错误
access_resource(should_fail=True)

# --- 预期输出 ---
# --- 尝试访问资源 (失败模式: False) ---
# 1. [try] 正在尝试打开资源...
# 2. [try] 资源访问成功！
# 4. [else] 成功处理资源: 宝贵的资源数据
# 5. [finally] 清理工作开始，关闭资源...
#
# --- 尝试访问资源 (失败模式: True) ---
# 1. [try] 正在尝试打开资源...
# 3. [except] 捕获到错误: 资源访问失败！
# 5. [finally] 清理工作开始，关闭资源...
```

### 🔍 Level 3: 对比学习（避免陷阱）
一个常见的误区是把本应放在 `else` 块中的代码错误地放在了 `try` 块里。这会让代码逻辑不清晰，也可能意外捕获了你不想处理的错误。

**陷阱：把所有代码都塞进 `try` 块**

```python
# === 错误用法 ===
# ❌ 将依赖于成功结果的代码也放入 try 块
user_input = {"name": "Alice", "age": "30"}
print("--- 错误用法 ---")
try:
    age_str = user_input["age"] # 这一行可能触发 KeyError
    age_num = int(age_str)      # 这一行可能触发 ValueError
    
    # 下面这行代码依赖于上面两行的成功，但它本身不会出错
    # 如果 age_num 转换时发生 ValueError，我们不希望“处理成功”被打印
    print(f"✅ 年龄处理成功，是 {age_num} 岁。") 
except KeyError:
    print("❌ 错误：字典中缺少 'age' 键。")
except ValueError:
    print("❌ 错误：年龄 '{age_str}' 不是一个有效的数字。")
# 解释: "处理成功" 的消息不应该在 try 块内。如果 int() 转换失败，
# 它后面的 print 语句就不会执行，这似乎没问题。但更好的做法是
# 将“成功后才执行”的逻辑明确地分离出来。


# === 正确用法 ===
# ✅ 只在 try 块中放置可能出错的代码，成功后的逻辑放入 else 块
user_input = {"name": "Bob", "age": "thirty"}
print("\n--- 正确用法 ---")
try:
    age_str = user_input["age"] 
    age_num = int(age_str)
except KeyError:
    print("❌ 错误：字典中缺少 'age' 键。")
except ValueError:
    # 这里的 age_str 变量是在 try 块中定义的，所以可以在这里使用
    print(f"❌ 错误：年龄 '{age_str}' 不是一个有效的数字。")
else:
    # 只有当 try 块中的所有代码都成功执行时，这里才会运行
    print(f"✅ 年龄处理成功，是 {age_num} 岁。")
# 解释: 这样代码的意图非常清晰。try 块