好的，总建筑师。模块化让我们的代码结构清晰，但再完美的结构也无法避免意外的发生。现在，我们将进入一个至关重要的领域——为我们的代码构建“安全网”。

我将依据您的设计图，续写关于“异常处理”的教程，确保我们的程序在面对突发状况时，依然能够保持优雅和稳定。

---

### 🎯 核心概念

异常处理机制允许我们在程序遇到错误（即“异常”）时，优雅地捕获并处理它们，而不是让整个程序因为一个可预见的错误而崩溃，从而确保代码的稳定性和健壮性。

### 💡 使用方式

Python 主要通过 `try...except...else...finally` 语句块来管理和响应程序运行时的异常。

```python
try:
    # 尝试执行的代码块，这里可能会发生错误
    # 例如：读取文件、进行数学计算、网络请求等
    ...
except SpecificError as e:
    # 如果在 try 块中发生了 SpecificError 类型的错误
    # 就会执行这里的代码来处理它，错误信息会赋值给变量 e
    ...
except AnotherError:
    # 也可以只捕获另一种错误类型，不关心具体的错误信息
    ...
else:
    # 如果 try 块中 *没有* 发生任何错误，则执行这里的代码
    # 适用于那些只有在主逻辑成功后才应执行的操作
    ...
finally:
    # 无论 try 块中是否发生错误，这个块中的代码 *总会* 被执行
    # 通常用于资源清理，如关闭文件、断开数据库连接等
    ...
```

### 📚 Level 1: 基础认知（30秒理解）

想象一下，你正在编写一个计算器，最常见的错误就是用户试图用一个数除以零。如果没有异常处理，程序会立刻崩溃。`try...except` 就是我们的救星。

```python
# main.py
numerator = 10
denominator = 0 # 故意设置一个会引发错误的除数

try:
    # 我们把可能会出错的代码，放进 try 语句块中
    result = numerator / denominator
    print(f"计算结果是: {result}")
except ZeroDivisionError:
    # 如果 try 块中发生了“除零错误”，程序会立即跳转到这里执行
    print("错误：除数不能为零！程序已捕获异常，将继续运行。")

print("程序执行完毕，没有因为错误而崩溃。")

# 预期输出:
# 错误：除数不能为零！程序已捕获异常，将继续运行。
# 程序执行完毕，没有因为错误而崩溃。
```
这个简单的例子展示了 `try...except` 的核心价值：它捕获了致命的 `ZeroDivisionError`，打印了一条友好的提示信息，并让程序继续执行下去。

### 📈 Level 2: 核心特性（深入理解）

掌握了基础的“抓捕”后，我们来学习如何更精细、更全面地处理各种异常情况。

#### 特性1: 捕获多种特定异常

一个代码块中可能发生多种不同类型的错误。我们可以设置多个 `except` 子句来分别处理它们，就像为不同的病人准备不同的药方。

```python
# main.py
def process_data(data_list):
    try:
        first_item = data_list[0]
        second_item = data_list[1]
        result = int(first_item) / int(second_item)
        print(f"处理成功，结果是: {result}")
    # 捕获当列表索引超出范围时发生的错误
    except IndexError:
        print("错误处理：输入的列表元素不足两个！")
    # 捕获当除数为零时发生的错误
    except ZeroDivisionError:
        print("错误处理：列表的第二个元素不能是'0'！")
    # 捕获当字符串无法转换为整数时发生的错误
    except ValueError:
        print("错误处理：列表中的元素必须是纯数字字符串！")

# 场景一：正常运行
print("场景一:")
process_data(['10', '2'])

# 场景二：索引错误
print("\n场景二:")
process_data(['5'])

# 场景三：除零错误
print("\n场景三:")
process_data(['10', '0'])

# 场景四：类型转换错误
print("\n场景四:")
process_data(['hello', 'world'])

# 预期输出:
# 场景一:
# 处理成功，结果是: 5.0
#
# 场景二:
# 错误处理：输入的列表元素不足两个！
#
# 场景三:
# 错误处理：列表的第二个元素不能是'0'！
#
# 场景四:
# 错误处理：列表中的元素必须是纯数字字符串！
```

#### 特性2: `else` 和 `finally` 的妙用

`else` 和 `finally` 子句为异常处理流程提供了更完整的控制。`else` 用于处理“未发生异常”的后续逻辑，而 `finally` 则确保某些清理工作无论如何都会执行。

```python
# main.py
def process_file(file_name, content_to_write):
    f = None  # 初始化变量 f
    try:
        print(f"\n[尝试] 准备打开文件 '{file_name}' 进行写入...")
        # 'w' 模式在目录不存在时会触发 FileNotFoundError
        f = open(file_name, 'w')
        # 模拟一个可能发生的错误：写入的内容不是字符串
        if not isinstance(content_to_write, str):
            # 主动抛出一个 TypeError
            raise TypeError("写入的内容必须是字符串！")
        f.write(content_to_write)
    except FileNotFoundError:
        print(f"[捕获] 错误：无法在路径 '{file_name}' 创建文件，请确保目录存在。")
    except TypeError as e:
        print(f"[捕获] 错误：{e}")
    else:
        # 如果 try 块中没有发生任何异常，这个块才会被执行
        print("[成功] 文件写入成功！")
    finally:
        # 无论是否发生异常，这个块总会被执行
        print("[清理] --- 进入清理阶段 ---")
        if f:  # 检查文件对象是否被成功创建
            f.close()
            print(f"[清理] 文件 '{file_name}' 已关闭。")
        else:
            print("[清理] 文件未被打开，无需关闭。")

# 场景一: 成功执行
process_file("log.txt", "一切正常。")

# 场景二: 发生 TypeError
process_file("error_log.txt", 12345)

# 场景三: 发生 FileNotFoundError (写入到不存在的目录)
process_file("non_existent_dir/some_log.txt", "此内容无法写入。")

# 预期输出:
# [尝试] 准备打开文件 'log.txt' 进行写入...
# [成功] 文件写入成功！
# [清理] --- 进入清理阶段 ---
# [清理] 文件 'log.txt' 已关闭。
#
# [尝试] 准备打开文件 'error_log.txt' 进行写入...
# [捕获] 错误：写入的内容必须是字符串！
# [清理] --- 进入清理阶段 ---
# [清理] 文件 'error_log.txt' 已关闭。
#
# [尝试] 准备打开文件 'non_existent_dir/some_log.txt' 进行写入...
# [捕获] 错误：无法在路径 'non_existent_dir/some_log.txt' 创建文件，请确保目录存在。
# [清理] --- 进入清理阶段 ---
# [清理] 文件未被打开，无需关闭。
```

### 🔍 Level 3: 对比学习（避免陷阱）

**主题：笼统捕获 `Exception` vs. 精准捕获特定异常**

初学者常犯的一个错误是使用 `except Exception:` 来捕获所有可能的错误。虽然这能防止程序崩溃，但它像是一个“黑洞”，吞噬了所有错误信息，让你难以调试和定位问题。

```python
# === 错误用法 ===
# ❌ 使用过于宽泛的 `except Exception:`
def bad_divider(a, b):
    try:
        result = a / b
        print(f"结果是: {result}")
    except Exception as e:
        # 这样写虽然能抓住所有错误，但你分不清具体是什么问题
        # 是除零了？还是类型不对？错误信息很模糊。
        print(f"发生了一个未知错误: {e}")

print("--- 错误用法演示 ---")
bad_divider(10, 0)       # 本应是 ZeroDivisionError
bad_divider(10, "2")     # 本应是 TypeError

# 解释为什么是错的:
# 两种完全不同的根本原因（除零、类型不匹配）被同一个模糊的错误信息掩盖了。
# 这使得调试变得困难，也无法针对性地给用户提供有用的反馈。
# 更糟糕的是，它可能捕获到你意想不到的错误（比如按 Ctrl+C 导致的 KeyboardInterrupt），
# 从而干扰程序的正常退出。

# === 正确用法 ===
# ✅ 分别捕获特定的异常
def good_divider(a, b):
    try:
        result = a / b
        print(f"结果是: {result}")
    except ZeroDivisionError:
        print("错误提示：除数不能为零。")
    except TypeError:
        print("错误提示：参与运算的必须是数字类型。")

print("\n--- 正确用法演示 ---")
good_divider(10, 0)
good_divider(10, "2")

# 解释为什么这样是对的:
# 通过精确捕获，我们可以为每种预期的错误提供清晰、具体的处理逻辑和用户提示。
# 这让代码更易读、更易维护，并且不会意外地隐藏其他未知或不应被捕获的系统级异常。
```

### 🚀 Level 4: 实战应用（真实场景）

**场景：** ⏳ **时空穿梭机能量核心校准系统**

我们要为一台时空穿梭机编写一个能量核心校准程序。校准过程非常精密，能量输入必须在安全阈值内，否则会导致时空涟漪。我们将创建一个自定义异常 `EnergyOverloadError` 来处理能量过载的危险情况。

```python
# main.py

# 1. 定义一个自定义异常，用于表示能量过载
class EnergyOverloadError(Exception):
    """当能量输入超过安全阈值时抛出此异常"""
    def __init__(self, level, message="能量输入严重过载！可能导致时空结构不稳定！"):
        self.level = level
        self.message = message
        super().__init__(f"{self.message} 当前能量值: {self.level}%")

# 2. 核心校准函数，可能会主动抛出异常
def calibrate_core(energy_level):
    """
    对能量核心进行校准。
    安全阈值为 0-100%。超过100%将抛出 EnergyOverloadError。
    """
    print(f"  [核心] 接收到校准指令，目标能量: {energy_level}%")
    if not 0 <= energy_level <= 100:
        # 使用 raise 关键字主动抛出我们自定义的异常
        raise EnergyOverloadError(energy_level)
    print(f"  [核心] 能量稳定在 {energy_level}%, 校准成功。")
    return True

# 3. 主控制程序，负责调用校准并处理各种情况
def run_calibration_sequence(target_level):
    """运行一次完整的校准序列"""
    print(f"\n🚀 === 开始校准序列，目标能量: {target_level}% === 🚀")
    try:
        # 尝试进行校准
        calibrate_core(target_level)
    except EnergyOverloadError as e:
        # 捕获我们自定义的异常
        print(f"  [警报!] 捕获到能量过载异常: {e}")
        print("  [措施] 紧急启动能量泄放程序...")
    except Exception as e:
        # 捕获其他意想不到的错误
        print(f"  [警报!] 发生未知系统错误: {e}")
    else:
        # 如果一切顺利
        print("  [状态] 校准序列顺利完成，未发生异常。")
    finally:
        # 无论结果如何，都要打印最终报告
        print("  [报告] 系统自检完成。校准序列结束。")

# --- 任务开始 ---
# 场景一: 安全的校准
run_calibration_sequence(85)

# 场景二: 危险的能量过载
run_calibration_sequence(150)

# 预期输出:
# 🚀 === 开始校准序列，目标能量: 85% === 🚀
#   [核心] 接收到校准指令，目标能量: 85%
#   [核心] 能量稳定在 85%, 校准成功。
#   [状态] 校准序列顺利完成，未发生异常。
#   [报告] 系统自检完成。校准序列结束。
#
# 🚀 === 开始校准序列，目标能量: 150% === 🚀
#   [核心] 接收到校准指令，目标能量: 150%
#   [警报!] 捕获到能量过载异常: 能量输入严重过载！可能导致时空结构不稳定！ 当前能量值: 150%
#   [措施] 紧急启动能量泄放程序...
#   [报告] 系统自检完成。校准序列结束。
```

### 💡 记忆要点
- **`try-except`是保险丝**: 将可能出错的代码放入`try`块，用`except`块处理“爆掉”的情况，防止整个程序“跳闸”。
- **捕获要精准**: 优先捕获具体的异常类型（如`ValueError`），而不是笼统的`Exception`，这样能让你的错误处理更有针对性，也避免隐藏未知Bug。
- **`else`是成功奖励，`finally`是责任**: `else`子句在`try`块顺利执行后运行，用于处理成功逻辑；`finally`子句无论成败都会执行，是清理资源的“责任区”。