好的，作为一名顶级的Python教育专家，我将为你生成关于 **“抛出异常 (raise)”** 的详细教学内容。

---

## 抛出异常 (raise)

### 🎯 核心概念
`raise` 语句允许程序员**主动触发**一个异常，而不是等待程序在运行时出错。它就像是在代码中设置一个“警报器”，当满足特定（通常是错误的）条件时，立即拉响警报，中断程序的正常流程。

### 💡 使用方式
`raise` 的基本语法非常直接：

```python
raise [ExceptionType]("可选的错误信息")
```

- `ExceptionType`: 你想要抛出的异常类型，例如 `ValueError`, `TypeError`, `RuntimeError` 等。
- `可选的错误信息`: 一个字符串，用于描述为什么会发生这个异常，这对于调试非常有帮助。

### 📚 Level 1: 基础认知（30秒理解）
想象一下，你需要编写一个函数来设置一个游戏角色的年龄，但年龄不能是负数。如果用户输入了负数，我们就应该主动告诉程序“这不对劲！”。

```python
def set_age(age):
    if age < 0:
        # 如果年龄小于0，这是无效的。我们主动抛出一个 ValueError 异常。
        raise ValueError("年龄不能为负数！")
    print(f"角色年龄已设置为: {age}")

try:
    set_age(25)
    set_age(-5) # 这行代码将触发异常
except ValueError as e:
    print(f"捕获到错误: {e}")

# 预期输出:
# 角色年龄已设置为: 25
# 捕获到错误: 年龄不能为负数！
```

### 📈 Level 2: 核心特性（深入理解）
`raise` 不仅仅是简单地抛出新异常，它还有更强大的用法。

#### 特性1: 重新抛出异常 (Re-raising)
在 `except` 块中，有时你可能想记录一个错误，然后将这个异常“原封不动”地再次抛出，让更高层级的代码去处理。这时，可以使用不带任何参数的 `raise`。

```python
def process_data(data):
    try:
        # 假设这里有一个复杂的操作，可能会导致 KeyError
        name = data['name']
        print(f"正在处理用户: {name}")
    except KeyError:
        print("日志：在处理数据时发现缺少'name'键。")
        # 将捕获到的原始异常重新抛出
        raise

try:
    process_data({'age': 30}) # 缺少 'name' 键
except KeyError:
    print("上层捕获：无法处理该数据，因为关键信息缺失。")

# 预期输出:
# 日志：在处理数据时发现缺少'name'键。
# 上层捕获：无法处理该数据，因为关键信息缺失。
```

#### 特性2: 异常链 (Exception Chaining)
有时，一个异常是由另一个异常引起的。为了不丢失原始的错误信息（根源），Python 3 允许你使用 `raise ... from ...` 来创建一个“异常链”。

这在调试时非常有用，因为它能告诉你“发生了A错误，而A错误是因为B错误引起的”。

```python
def install_game_mod(mod_file):
    try:
        with open(mod_file, 'r') as f:
            content = f.read()
    except FileNotFoundError as e:
        # 抛出一个更具体的应用层异常，但同时保留原始的 FileNotFoundError 信息
        raise RuntimeError("无法加载Mod配置！") from e

try:
    install_game_mod("super_sword.mod") # 假设这个文件不存在
except RuntimeError as e:
    print(f"安装失败: {e}")
    print(f"根本原因: {e.__cause__}")

# 预期输出:
# 安装失败: 无法加载Mod配置！
# 根本原因: [Errno 2] No such file or directory: 'super_sword.mod'
```

### 🔍 Level 3: 对比学习（避免陷阱）
一个常见的错误是在 `except` 块中抛出一个全新的异常，从而丢失了原始错误的上下文信息。

```python
# === 错误用法 ===
# ❌ 在 except 块中抛出新异常，丢失了原始错误信息
def calculate_ratio_bad(a, b):
    try:
        result = a / b
    except ZeroDivisionError:
        # 这种做法会隐藏掉原始的 ZeroDivisionError Traceback
        # 对于调试者来说，他们不知道最初的问题是“除以零”。
        raise ValueError("输入参数无效")

try:
    calculate_ratio_bad(10, 0)
except ValueError as e:
    print(f"错误: {e}")
    # 你无法在这里轻易知道根本原因是 ZeroDivisionError

# === 正确用法 ===
# ✅ 使用 `raise ... from ...` 保留原始异常信息
def calculate_ratio_good(a, b):
    try:
        result = a / b
    except ZeroDivisionError as e:
        # 这样，新的 ValueError 包含了对原始 ZeroDivisionError 的引用
        # 调试信息会更完整，清晰地展示了异常链。
        raise ValueError("输入参数无效") from e

try:
    calculate_ratio_good(10, 0)
except ValueError as e:
    print(f"正确做法捕获的错误: {e}")
    print(f"错误的根本原因: {e.__cause__}")
```

### 🚀 Level 4: 实战应用（真实场景）
**场景：** 🍕 自动化披萨订单处理器

我们的披萨店有一个自动下单系统。这个系统需要验证订单的有效性：
1.  必须至少选择一种配料。
2.  披萨尺寸必须是 "小", "中", "大" 中的一种。
3.  如果选择 "菠萝" 作为配料，系统会“礼貌地”拒绝（抛出异常！）。

```python
class PizzaOrderError(Exception):
    """自定义一个披萨订单相关的异常类型"""
    pass

def process_pizza_order(size, toppings):
    """
    处理披萨订单，并对无效订单抛出异常。
    """
    print(f"\n⏳ 正在处理您的订单... 尺寸: {size}, 配料: {toppings}")

    # 规则 2: 验证尺寸
    valid_sizes = ["小", "中", "大"]
    if size not in valid_sizes:
        raise PizzaOrderError(f"无效的尺寸: '{size}'。我们只提供 {valid_sizes}。")

    # 规则 1: 验证配料数量
    if not toppings: # 列表为空
        raise PizzaOrderError("订单无效：您必须至少选择一种配料！")

    # 规则 3: 验证是否包含菠萝
    if "菠萝" in toppings:
        raise PizzaOrderError("抱歉，我们的披萨店坚决反对在披萨上放菠萝！🍍🚫")
        
    print(f"✅ 订单有效！一个美味的 {size} 号 {', '.join(toppings)} 披萨正在制作中...")

# --- 模拟顾客下单 ---

# 案例1: 成功的订单
try:
    process_pizza_order("大", ["芝士", "蘑菇", "香肠"])
except PizzaOrderError as e:
    print(f"❌ 订单失败: {e}")

# 案例2: 尺寸错误的订单
try:
    process_pizza_order("特大", ["牛肉"])
except PizzaOrderError as e:
    print(f"❌ 订单失败: {e}")

# 案例3: 没有配料的订单
try:
    process_pizza_order("中", [])
except PizzaOrderError as e:
    print(f"❌ 订单失败: {e}")

# 案例4: 挑战底线的订单
try:
    process_pizza_order("小", ["培根", "菠萝"])
except PizzaOrderError as e:
    print(f"❌ 订单失败: {e}")

# 预期输出:
#
# ⏳ 正在处理您的订单... 尺寸: 大, 配料: ['芝士', '蘑菇', '香肠']
# ✅ 订单有效！一个美味的 大 号 芝士, 蘑菇, 香肠 披萨正在制作中...
#
# ⏳ 正在处理您的订单... 尺寸: 特大, 配料: ['牛肉']
# ❌ 订单失败: 无效的尺寸: '特大'。我们只提供 ['小', '中', '大']。
#
# ⏳ 正在处理您的订单... 尺寸: 中, 配料: []
# ❌ 订单失败: 订单无效：您必须至少选择一种配料！
#
# ⏳ 正在处理您的订单... 尺寸: 小, 配料: ['培根', '菠萝']
# ❌ 订单失败: 抱歉，我们的披萨店坚决反对在披萨上放菠萝！🍍🚫
```

### 💡 记忆要点
- **主动出击**: `raise` 是用来主动创造并抛出错误的，而不是被动等待错误发生。
- **选择合适的“弹药”**: 抛出语义清晰的异常类型（如 `ValueError`, `TypeError