好的，我将以一名专业的JavaScript教育专家的身份，为你创建关于 `try-catch-finally` 的教学内容。内容将严格遵循你提出的所有要求，包括格式、代码块的完整性、有趣的实战场景等。

---

## try-catch-finally

### 🎯 核心概念
`try-catch-finally` 是一种错误处理机制，它允许我们**预见并处理**可能出错的代码，从而避免整个程序因一个错误而崩溃，保证程序的健壮性和稳定性。

### 📚 Level 1: 基础认知（30秒理解）
想象一下你在尝试做一件可能会失败的事情，比如调用一个不存在的函数。如果没有保护，程序就会立刻“报错”并停止运行。`try-catch` 就像一个安全网，能接住这个错误，让程序继续走下去。

```javascript
console.log("程序开始运行...");

try {
  // 我们尝试调用一个不存在的函数，这一定会引发错误
  console.log("正在尝试执行危险操作...");
  nonExistentFunction(); 
  console.log("这行代码不会被执行，因为上面出错了。");
} catch (error) {
  // 如果 try 块中发生错误，代码会立即跳转到这里
  console.log("噢！我们抓住了一个错误！");
  console.log("错误信息:", error.message);
}

console.log("程序并没有崩溃，而是继续执行到了这里。");
```

### 📈 Level 2: 核心特性（深入理解）
`try-catch` 不仅仅是捕获错误，它还有更强大的功能。

#### 特性1: `finally` 块的保证执行
`finally` 块中的代码非常特别，**无论 `try` 块是否发生错误，它最后总会被执行**。这对于执行“清理”工作（如关闭文件、断开网络连接等）非常有用。

```javascript
function testFinally(shouldThrowError) {
  try {
    console.log("进入 try 块...");
    if (shouldThrowError) {
      // 抛出一个自定义错误
      throw new Error("一个预料之中的错误发生了！");
    }
    console.log("try 块成功执行完毕。");
    // 即使这里有 return，finally 依然会执行
    return "从 try 返回"; 
  } catch (error) {
    console.error("进入 catch 块，捕获到错误:", error.message);
    // 即使这里有 return，finally 依然会执行
    return "从 catch 返回";
  } finally {
    // 无论如何，这个 console.log 都会被打印出来
    console.log("进入 finally 块，执行清理工作...");
  }
}

console.log("--- 场景1: 没有发生错误 ---");
const result1 = testFinally(false);
console.log("函数最终返回值:", result1);

console.log("\n--- 场景2: 发生了错误 ---");
const result2 = testFinally(true);
console.log("函数最终返回值:", result2);
```

#### 特性2: `catch` 块的错误对象
当 `catch` 捕获到错误时，它会接收到一个“错误对象”（通常命名为 `error` 或 `e`）。这个对象包含了错误的详细信息，帮助我们更好地理解问题所在。

```javascript
try {
  // 让我们制造一个引用错误 (ReferenceError)
  let user = { name: "Alice" };
  console.log(user.profile.age); // user.profile 是 undefined，再访问 .age 就会报错
} catch (error) {
  console.log("捕获到了一个错误！下面是它的详细信息：");
  console.log("------------------------------------");
  // error.name: 错误的类型
  console.log("错误类型 (name):", error.name); 
  // error.message: 错误的具体描述
  console.log("错误信息 (message):", error.message);
  // error.stack: 错误的堆栈跟踪，显示了错误发生的位置
  console.log("堆栈跟踪 (stack):", error.stack);
  console.log("------------------------------------");
  console.log("我们可以根据这些信息来修复bug或者给用户友好提示。");
}
```

### 🔍 Level 3: 对比学习（避免陷阱）
不使用 `try-catch` 处理潜在错误是程序变得脆弱的常见原因。

```javascript
// 一个模拟从服务器获取数据的函数，但数据可能是坏的
function parseUserData(jsonString) {
  // JSON.parse 对于格式错误的字符串会抛出错误
  return JSON.parse(jsonString);
}

console.log("=== 错误用法 ❌ ===");
// 假设我们从服务器收到了一个损坏的JSON字符串
const badJson = '{"name": "Bob", "age": 40'; // 结尾缺少 '}'

try {
    console.log("程序开始，尝试解析坏数据...");
    const user = parseUserData(badJson); // 这一行会抛出错误
    console.log("用户数据:", user); // 这行永远不会执行
    console.log("后续重要代码1"); // 这行永远不会执行
    console.log("后续重要代码2"); // 这行永远不会执行
} catch(e) {
    // 虽然这里有个空的try-catch，但它包裹的范围太小了，没有抓住真正的错误。
    // 真正的错误发生在函数内部，而函数调用本身没有被包裹。
    // 为了演示目的，我们注释掉这个错误的try-catch，直接展示裸奔代码的后果。
}

// 如果我们直接调用 parseUserData(badJson) 而不包裹它，程序会在这里崩溃。
// 为了让整个示例能运行，我们用一个 catch 来模拟程序崩溃的效果。
try {
    parseUserData(badJson);
} catch(e) {
    console.error("程序在解析时崩溃了！错误:", e.message);
    console.error("后面的所有代码都不会执行，这可能会导致应用白屏或功能中断。");
}


console.log("\n=== 正确用法 ✅ ===");
const goodJson = '{"name": "Charlie", "age": 25}';

function processDataSafely(jsonString) {
    console.log(`正在尝试处理数据: ${jsonString}`);
    try {
        const user = parseUserData(jsonString);
        console.log("✅ 数据解析成功! 用户:", user.name);
    } catch (error) {
        console.error("❌ 数据解析失败! 但程序不会崩溃。");
        console.error("我们可以记录这个错误，并给用户一个友好的提示，比如 '数据加载失败，请稍后重试'。");
    }
    console.log("...无论成功与否，处理流程继续...");
}

processDataSafely(goodJson); // 处理正确的数据
processDataSafely(badJson);  // 处理错误的数据
console.log("程序优雅地处理了所有情况，并顺利执行到最后。");
```

### 🚀 Level 4: 实战应用（真实场景）
**🚀 科幻冒险：外星信号翻译器**

你是一名星际宇航员，你的任务是解码从遥远星系传来的信号。这些信号可能是友好的问候，也可能是危险的警告，甚至可能只是无意义的宇宙噪音。你的翻译器必须足够强大，能够处理各种情况而不会崩溃。

```javascript
// 你的高科技外星信号翻译器
function translateAlienSignal(signal) {
  console.log(`\n--- 接收到新信号: "${signal}" ---`);
  
  try {
    console.log("启动量子解码器，尝试解析信号结构...");
    // 信号标准格式是JSON，我们尝试解析它
    const data = JSON.parse(signal);
    console.log("✅ 解码成功！正在分析内容...");
    
    // 根据信号类型执行不同操作
    if (data.type === 'greeting' && data.from) {
      console.log(`👽 [友好消息] 来自 ${data.from} 星球: "${data.message}"`);
    } else if (data.type === 'warning') {
      console.log(`🚨 [紧急警报] 来源 ${data.from || '未知'}: "${data.message}"`);
      console.log("    请舰长立刻注意！");
    } else {
      // 捕获一个我们自己定义的“逻辑错误”
      throw new Error("无法识别的信号协议！");
    }
    
  } catch (error) {
    // 错误处理中心，根据不同错误类型做出反应
    if (error instanceof SyntaxError) {
      // JSON.parse 失败会抛出 SyntaxError
      console.error("❌ 解码失败！信号可能已在传输中损坏，或只是宇宙背景噪音。");
      console.error("   技术日志:", error.message);
    } else {
      // 其他所有错误（比如我们自己抛出的那个）
      console.warn(`⚠️ 捕获到未知逻辑错误: ${error.message}`);
      console.warn("   这可能是来自一个未知文明的新协议，已记录待分析。");
    }
  } finally {
    // 无论解码成功与否，都要关闭接收频道以节省能量
    console.log("...通讯频道已关闭，等待下一段信号。");
  }
}

// 模拟一天中接收到的几段不同信号
const signal1 = '{"type": "greeting", "from": "半人马座α星", "message": "我们带来了和平与知识。"}';
const signal2 = '{"type": "warning", "from": "猎户座悬臂", "message": "检测到伽马射线暴，立刻规避！"}';
const signal3 = '滋...滋滋...宇宙...风暴...干扰...'; // 损坏的信号
const signal4 = '{"type": "trade_offer", "item": "曲率引擎图纸"}'; // 未知协议的信号

translateAlienSignal(signal1);
translateAlienSignal(signal2);
translateAlienSignal(signal3);
translateAlienSignal(signal4);
```

### 💡 记忆要点
- **要点1**：`try` 块用于包裹“可能出错”的代码，像一个代码的“安全气囊”。
- **要点2**：`catch` 块在 `try` 块发生错误时被触发，用于捕获错误并执行补救措施，防止程序崩溃。
- **要点3**：`finally` 块是“清理大师”，无论成功还是失败，它包含的代码最后总会被执行。

<!--
metadata:
  syntax: try-catch, finally, throw, instanceof
  pattern: error-handling, control-flow
  api: JSON.parse, console.log, console.error, console.warn, Error
  concept: error-handling, exception, control-flow
  difficulty: intermediate
  dependencies: [无]
  related: []
-->